{
  "cve_id": "CVE-2024-37032",
  "timestamp": "2025-01-14 16:58:43",
  "phases": {
    "primary": {
      "completed": true,
      "timestamp": "2025-01-10 10:40:09"
    },
    "secondary": {
      "completed": true,
      "timestamp": "2025-01-11 20:55:44"
    },
    "extraction": {
      "completed": true,
      "timestamp": "2025-01-12 20:50:39"
    }
  },
  "urls": [
    {
      "url": "https://github.com/ollama/ollama/blob/adeb40eaf29039b8964425f69a9315f9f1694ba8/server/modelpath_test.go#L41-L58",
      "status": "success",
      "reason": null,
      "timestamp": "2025-01-14 11:33:06"
    },
    {
      "url": "https://github.com/ollama/ollama/compare/v0.1.33...v0.1.34",
      "status": "success",
      "reason": null,
      "timestamp": "2025-01-14 11:33:06"
    },
    {
      "url": "https://github.com/ollama/ollama/pull/4175",
      "status": "success",
      "reason": null,
      "timestamp": "2025-01-14 11:33:06"
    },
    {
      "url": "https://www.vicarius.io/vsociety/posts/probllama-in-ollama-a-tale-of-a-yet-another-rce-vulnerability-cve-2024-37032",
      "status": "success",
      "reason": null,
      "timestamp": "2025-01-14 11:33:06"
    }
  ]
}