{
  "cve_id": "CVE-2021-23556",
  "timestamp": "2025-01-14 00:42:01",
  "phases": {
    "primary": {
      "completed": true,
      "timestamp": "2025-01-08 10:43:25"
    },
    "secondary": {
      "completed": true,
      "timestamp": "2025-01-09 11:54:57"
    },
    "extraction": {
      "completed": true,
      "timestamp": "2025-01-08 23:35:40"
    }
  },
  "urls": [
    {
      "url": "https://github.com/Guake/guake/issues/1796",
      "status": "success",
      "reason": null,
      "timestamp": "2025-01-10 10:39:06"
    },
    {
      "url": "https://github.com/Guake/guake/pull/2017",
      "status": "success",
      "reason": null,
      "timestamp": "2025-01-10 10:39:06"
    },
    {
      "url": "https://github.com/Guake/guake/pull/2017/commits/e3d671120bfe7ba28f50e256cc5e8a629781b888",
      "status": "success",
      "reason": null,
      "timestamp": "2025-01-10 10:39:06"
    },
    {
      "url": "https://github.com/Guake/guake/releases",
      "status": "success",
      "reason": null,
      "timestamp": "2025-01-10 10:39:06"
    },
    {
      "url": "https://snyk.io/vuln/SNYK-PYTHON-GUAKE-2386334",
      "status": "success",
      "reason": null,
      "timestamp": "2025-01-10 10:39:06"
    }
  ]
}